---
layout: post
title: "[kotlin] 코틀린(Kotlin) Flow의 에러 처리"
description: " "
date: 2023-12-14
tags: [kotlin]
comments: true
share: true
---
코틀린의 Flow는 비동기적으로 값을 내보내는 데이터 스트림을 나타내는 코루틴 기반 API입니다. Flow를 사용하면 데이터 스트림을 효과적으로 처리할 수 있지만, 때로는 에러 처리가 필요합니다.

이번 글에서는 코틀린 Flow에서의 에러 처리 방법과 주의할 점에 대해 알아보겠습니다.

## Flow에서의 에러 처리
Flow 내에서 발생하는 에러를 처리하기 위해서는 `catch` 연산자를 사용할 수 있습니다. `catch` 연산자를 사용하여 Flow에서 발생하는 예외를 처리하거나 대체값을 제공할 수 있습니다.

아래는 기본적인 형태의 `catch` 연산자를 사용한 예제입니다.

```kotlin
flow {
    emit(1)
    throw Exception("Error occurred")
}.catch { e ->
    println("Caught an exception: $e")
    emit(99)
}.collect { value ->
    println("Received value: $value")
}
```

위 예제에서는 Flow에서 예외가 발생하면 `catch` 블록 내에서 해당 예외를 처리하고, `emit(99)`를 통해 대체값을 제공하고 있습니다.

## 에러 전파
기존의 예외를 `catch` 블록에서 처리하고 대체값을 제공했더라도, 해당 Flow를 수집하는 과정에서 새로운 예외가 발생할 수 있습니다. 기존의 예외와 새로운 예외 모두 발생 가능한데, 이를 "에러 전파"라고 합니다.

에러 전파를 방지하기 위해서는 `catch` 블록 내에서 새로운 예외가 발생하지 않도록 주의해야 합니다.

## 취소 가능한 Flow에서의 에러 처리
Flow는 취소 가능한(cancellable) 특성을 가지고 있습니다. Flow의 `collect` 작업 중에 해당 Flow의 수집을 중단시킬 수 있고, 이때 예외가 발생할 수 있습니다. 따라서 취소 가능한 Flow에서는 이러한 예외를 처리하는 방안을 마련해야 합니다.

## 마치며
코틀린 Flow를 사용할 때에는 예외 처리에 대한 각별한 주의가 필요합니다. 에러 처리 방법을 잘 이해하고 적절히 활용하여 안정적인 비동기적 데이터 처리를 구현할 수 있도록 노력해야 합니다.

이상으로 코틀린 Flow에서의 에러 처리에 대해 알아보았습니다.