---
layout: post
title: "[kotlin] 중첩된 예외 처리"
description: " "
date: 2023-12-18
tags: [kotlin]
comments: true
share: true
---

안녕하세요! 이번 포스트에서는 Kotlin에서 중첩된 예외 처리에 대해 알아보겠습니다. 

## 중첩된 예외란?

중첩된 예외란 **하나의 예외가 다른 예외를 유발**하는 상황을 의미합니다. 이는 **예외 처리**를 할 때 유용한 정보를 제공해 줄 수 있습니다.

Kotlin에서는 `catch` 블록 내에서 다시 예외를 던질 수 있습니다. 이때 기존 예외를 중첩하여 더 자세한 정보를 담은 예외로 던질 수 있습니다. 이는 디버깅과 로깅에 매우 유용합니다.

## 예제 코드

아래 예제에서는 중첩된 예외 처리를 다룹니다. 

```kotlin
try {
    // 코드 실행
} catch (e: IOException) {
    throw CustomException("Something went wrong", e)
}
```

위의 코드에서는 `IOException`이 발생했을 때, `CustomException`을 발생시키면서 기존의 `IOException`을 중첩하여 전달하고 있습니다.

## 중첩된 예외 접근

중첩된 예외에 접근하기 위해서는 `cause` 속성을 사용할 수 있습니다. 아래는 중첩된 예외를 처리하는 간단한 예제입니다.

```kotlin
try {
    // 코드 실행
} catch (e: CustomException) {
    val originalException = e.cause
    // 중첩된 예외에 대한 처리
}
```

## 결론

Kotlin에서 중첩된 예외 처리는 복잡한 예외 상황을 다루는 데 유용합니다. 중첩된 예외를 활용하여 예외에 대한 보다 자세한 정보를 전달하고 처리할 수 있습니다.

이상으로 Kotlin의 중첩된 예외 처리에 대한 간단한 소개였습니다. 감사합니다!

## 참고 자료
- [Kotlin 공식 문서](https://kotlinlang.org/docs/exception-handling.html)

다음 포스트에서는 Java에서의 중첩된 예외 처리에 대해 알아보겠습니다. 기대해주세요!